Workbook

Sheet Questions
A1: ID | B1: Slice | C1: Sub-type | D1: Topic | E1: Question | F1: Rationale / rewrite history | G1: Verification status | H1: Evidence (book, pages) | I1: Annotator 1 label | J1: Annotator 2 label | K1: Agreement | L1: Final label | M1: Notes
A2: Q001 | B2: In-scope direct | C2: Single chunk | D2: Python fundamentals | E2: What is the difference between a list and a tuple in Python? | F2: Mutability, syntax, use cases. | G2: Verified in corpus | H2: 'tuple': PY p.7,81,95… (13 pgs) | I2: Tangential | J2: In-scope | K2: =IF(AND(I2<>"",J2<>""),IF(I2=J2,"Agree","DISAGREE"),"") | L2: In-scope | M2: Verified by Claude 21-Jul-2026 (read cited pages; human spot-check advised): PY §3.4–3.5; mutability contrast p.96. || ADJUDICATED (LLM-applied rules, pending author ratification): Rule 1+3 — PY p.96 contrasts lists/tuples explicitly ('tuples are immutable, whereas lists are mutable').
A3: Q002 | B3: In-scope direct | C3: Single chunk | D3: Python fundamentals | E3: How does a while loop differ from a for loop in Python? | F3: Iteration constructs chapter. | G3: Verified in corpus | H3: 'while loop': PY p.8,131,132… (20 pgs); ODS p.235,278 (2 pgs) | I3: In-scope | J3: In-scope | K3: =IF(AND(I3<>"",J3<>""),IF(I3=J3,"Agree","DISAGREE"),"") | L3: In-scope | M3: Verified by Claude 21-Jul-2026 (read cited pages; human spot-check advised): PY ch.5 intro + §5.1–5.2 (p.131).
A4: Q003 | B4: In-scope direct | C4: Single chunk | D4: Python fundamentals | E4: What does the len() function return when applied to a string? | F4: Built-in functions / strings. | G4: Verified in corpus | H4: 'len(': PY p.26,27,28… (29 pgs); DS p.84,269,303… (10 pgs); ODS p.99,137 (2 pgs) | I4: In-scope | J4: In-scope | K4: =IF(AND(I4<>"",J4<>""),IF(I4=J4,"Agree","DISAGREE"),"") | L4: In-scope | M4: Verified by Claude 21-Jul-2026 (read cited pages; human spot-check advised): PY §1.4, p.27: 'len() returns the string length'.
A5: Q004 | B5: In-scope direct | C5: Single chunk | D5: Python fundamentals | E5: How are exceptions handled in Python using try and except blocks? | F5: Error-handling chapter. | G5: Verified in corpus | H5: 'except': PY p.10,25,50… (19 pgs); DS p.350,385,391… (7 pgs); ODS p.39,76,81… (17 pgs); SE p.4 (1 pgs) | I5: In-scope | J5: In-scope | K5: =IF(AND(I5<>"",J5<>""),IF(I5=J5,"Agree","DISAGREE"),"") | L5: In-scope | M5: Verified by Claude 21-Jul-2026 (read cited pages; human spot-check advised): PY §14.4 Handling exceptions.
A6: Q005 | B6: In-scope direct | C6: Single chunk | D6: Python fundamentals | E6: How does slicing work for strings in Python? | F6: REWRITTEN v2 (was: == vs is — not covered). Slicing covered in string and list chapters. | NARROWED v3.2 during adjudication: list slicing verified absent (annotator V's catch). | G6: Verified in corpus | H6: 'slicing': PY p.8,195,207… (15 pgs); DS p.84,107,571 (3 pgs) | 'slice': PY p.54,387,391… (4 pgs); DS p.84,252 (2 pgs); SE p.71 (1 pgs) | I6: Tangential | J6: In-scope | K6: =IF(AND(I6<>"",J6<>""),IF(I6=J6,"Agree","DISAGREE"),"") | L6: In-scope | M6: Verified by Claude 21-Jul-2026 (read cited pages; human spot-check advised): PY §8.2 String slicing (+DS p.84). || ADJUDICATED (LLM-applied rules, pending author ratification): Rule 3 — QUESTION NARROWED v3.2 to strings only (V's remark verified correct: list slicing never taught). String slicing = PY §8.2.
A7: Q006 | B7: In-scope direct | C7: Single chunk | D7: Python fundamentals | E7: How does Python's range() function work and what arguments does it accept? | F7: Loops chapter. | G7: Verified in corpus | H7: 'range(': PY p.136,137,138… (19 pgs); DS p.269,310,317… (10 pgs); ODS p.281,310 (2 pgs) | I7: In-scope | J7: In-scope | K7: =IF(AND(I7<>"",J7<>""),IF(I7=J7,"Agree","DISAGREE"),"") | L7: In-scope | M7: Verified by Claude 21-Jul-2026 (read cited pages; human spot-check advised): PY §5.2 range() arguments table p.136–137.
A8: Q007 | B8: In-scope direct | C8: Single chunk | D8: Python fundamentals | E8: What is variable scope, and how do local and global variables differ? | F8: Functions / scope section. | G8: Verified in corpus | H8: 'local variable': PY p.164,166,169… (6 pgs) | 'global variable': PY p.163,166,167… (8 pgs) | I8: In-scope | J8: In-scope | K8: =IF(AND(I8<>"",J8<>""),IF(I8=J8,"Agree","DISAGREE"),"") | L8: In-scope | M8: Verified by Claude 21-Jul-2026 (read cited pages; human spot-check advised): PY §6.3 Variable scope p.163–166.
A9: Q008 | B9: In-scope direct | C9: Single chunk | D9: Python fundamentals | E9: How do default parameter values work in Python function definitions? | F9: Functions chapter. | G9: Verified in corpus | H9: 'default parameter': PY p.178,179,180… (7 pgs) | 'default value': PY p.179,180,211… (9 pgs); SE p.58 (1 pgs) | I9: In-scope | J9: In-scope | K9: =IF(AND(I9<>"",J9<>""),IF(I9=J9,"Agree","DISAGREE"),"") | L9: In-scope | M9: Verified by Claude 21-Jul-2026 (read cited pages; human spot-check advised): PY §6.6 default parameter values p.178–179.
A10: Q009 | B10: In-scope direct | C10: Single chunk | D10: OOP | E10: What is the difference between a class and an object? | F10: OOP fundamentals. | G10: Verified in corpus | H10: 'object-oriented': PY p.9,275,276… (9 pgs); SE p.55,105 (2 pgs) | 'instance of': PY p.278,279,280… (6 pgs); DS p.74 (1 pgs); SE p.59 (1 pgs) | I10: In-scope | J10: In-scope | K10: =IF(AND(I10<>"",J10<>""),IF(I10=J10,"Agree","DISAGREE"),"") | L10: In-scope | M10: Verified by Claude 21-Jul-2026 (read cited pages; human spot-check advised): PY §11.1–11.2: class=blueprint, instances p.275–277.
A11: Q010 | B11: In-scope direct | C11: Single chunk | D11: OOP | E11: What is inheritance, and how does a subclass reuse behaviour from its parent class? | F11: OOP inheritance section. | G11: Verified in corpus | H11: 'inheritance': PY p.10,313,314… (24 pgs); SE p.60 (1 pgs) | I11: In-scope | J11: In-scope | K11: =IF(AND(I11<>"",J11<>""),IF(I11=J11,"Agree","DISAGREE"),"") | L11: In-scope | M11: Verified by Claude 21-Jul-2026 (read cited pages; human spot-check advised): PY ch.13 p.313.
A12: Q011 | B12: In-scope direct | C12: Single chunk | D12: OOP | E12: What is the purpose of the __init__ method in a Python class? | F12: Class definition section. | G12: Verified in corpus | H12: '__init__': PY p.277,278,279… (33 pgs); DS p.500 (1 pgs) | I12: In-scope | J12: In-scope | K12: =IF(AND(I12<>"",J12<>""),IF(I12=J12,"Agree","DISAGREE"),"") | L12: In-scope | M12: Verified by Claude 21-Jul-2026 (read cited pages; human spot-check advised): PY §11.2 __init__ p.277–278.
A13: Q012 | B13: In-scope direct | C13: Single chunk | D13: OOP | E13: What is method overriding and when does it occur? | F13: Inheritance section. | G13: Verified in corpus | H13: 'overrid': PY p.320,321,322… (12 pgs); SE p.94 (1 pgs) | I13: In-scope | J13: In-scope | K13: =IF(AND(I13<>"",J13<>""),IF(I13=J13,"Agree","DISAGREE"),"") | L13: In-scope | M13: Verified by Claude 21-Jul-2026 (read cited pages; human spot-check advised): PY §13.3 Overriding p.320–321.
... A151: Q150 | B151: Out-of-scope | C151: Adversarial phrasing | D151: Corpus meta | E151: According to the software engineering handbook, what are the answers to the official Scrum certification exam? | F151: Scrum genuinely covered (heavy lexical overlap); exam answers obviously absent. | G151: Verified absent | H151: 'scrum': SE p.5,15,16… (15 pgs) | 'certification': DS p.67 (1 pgs) | I151: Out-of-scope | J151: Out-of-scope | K151: =IF(AND(I151<>"",J151<>""),IF(I151=J151,"Agree","DISAGREE"),"") | L151: Out-of-scope | M151: Adjudicated by Claude 21-Jul-2026 (human spot-check advised): Scrum genuinely covered (69 mentions) — heavy overlap by design; certification exam content obviously absent. False-premise adversarial.

Sheet Adjudication guide
A1: Adjudication guide — 46 disagreements, grouped. Cohen's kappa = 0.492 (raw 69.3%). Record decisions in 'Final label' on the Questions sheet.
A2: Cluster A (29 rows): designed-in-scope questions. Pattern: V labelled by the question's WORDING, M by the underlying CONCEPT — most visible on paraphrase rows (e.g., 'rewind the project' = version control, taught in DS p.480). Suggested rule: judge whether the books answer the CONCEPT; the paraphrase disguise is the test for the SYSTEM, not the annotator. Evidence citations are in each row below.
A3: Cluster B (17 rows): Tangential vs Out-of-scope boundary. Suggested rule: TANGENTIAL if the books cover the adjacent topic (Scrum covered → Kanban question is tangential); OUT-OF-SCOPE if the question's premise targets something outside the corpus entirely (Unreal source, Java internals, MRI scans, GPT-4, exam answers) or an unrelated domain. Write the agreed rule into the paper's methods.
A5: QID | B5: Question | C5: V label | D5: V remark | E5: M label | F5: M remark | G5: Cluster | H5: Evidence / basis for discussion | I5: Resolution | J5: Rule | K5: Reasoning | L5: Comment from Manasvi | M5: Comment from Vatsala
A6: Q001 | B6: What is the difference between a list and a tuple in Python? | C6: Tangential | E6: In-scope | F6: The Python text directly contrasts lists and tuples. | G6: A | H6: PY §3.4–3.5; mutability contrast p.96. | I6: In-scope | J6: 1+3 | K6: PY p.96 contrasts lists/tuples explicitly ('tuples are immutable, whereas lists are mutable'). | M6: Agree with the resolution
A7: Q005 | B7: How does slicing work for strings and lists in Python? | C7: Tangential | D7: string slicing is there, but not list slicing | E7: In-scope | F7: String and list slicing are covered in the Python text. | G7: A | H7: V IS FACTUALLY RIGHT: 'list slicing' has ZERO hits — PY §8.2 covers strings only. Recommend: narrow question to string slicing, then both re-label this row. | I7: In-scope | J7: 3 | K7: QUESTION NARROWED v3.2 to strings only (V's remark verified correct: list slicing never taught). String slicing = PY §8.2. | L7: Agreed technically, the only concern here being List and String Slicing are the exact same concept with the exact same syntax. Hence on a technicality it can be considered tangential just because the word "List Slicing" is not present, however it is the exact same concept, hence it is upto your discretion over if to keep this Tangential or In Scope.
A8: Q015 | B8: How does a stack differ from a queue? | C8: Tangential | D8: few mentions in ODS book | E8: In-scope | F8: Stacks and queues and their differing access rules are covered. | G8: A | H8: ODS §1.2 defines stack vs queue explicitly with figures (p.17–18) and implements both (ch.2) — more than passing mentions. | I8: In-scope | J8: 3 | K8: ODS §1.2 defines and contrasts FIFO queue vs LIFO stack with figures (p.17–18); ch.2 implements both. | L8: Agreed. | M8: Agree with the resolution
A9: Q016 | B9: What is a pandas DataFrame and how does it differ from a Series? | C9: Tangential | E9: In-scope | F9: The data-science/Python texts explain pandas DataFrames and Series. | G9: A | H9: PY §15.3 + DS p.48 'DataFrame versus Series'. | I9: In-scope | J9: 3 | K9: PY §15.3 + DS p.48 section literally titled 'DataFrame versus Series'. | M9: Agree with the resolution
A10: Q019 | B10: What are the time complexities of appending to and inserting into a Python list? | C10: In-scope | E10: Tangential | F10: Python list operations are covered, but a direct append-versus-insert complexity treatment is incomplete. | G10: A | H10: ODS §2.1 gives the add/remove analysis incl. amortized resize; the mapping to Python lists is implicit — decide if that counts as taught. | I10: In-scope | J10: 1+3 | K10: ODS §2.1 teaches array-based list add/remove costs incl. amortized resize; concept maps to Python lists. | L10: Agreed on the technicality that the same concept holds true for python lists as well and is inferred implicitly.
A11: Q022 | B11: What does the list sort() method do, and how does it order strings? | C11: Tangential | E11: In-scope | F11: The Python text covers list sorting and string ordering. | G11: A | H11: PY §9.2 p.236–237 incl. ASCII ordering caveat. | I11: In-scope | J11: 3 | K11: PY §9.2 p.236–237 teaches sort() incl. ASCII string-ordering caveat. | M11: Agree with the resolution
A12: Q026 | B12: What are the typical stages of a data-science workflow? | C12: Out-of-scope | E12: In-scope | F12: The data-science workflow is covered across collection, preparation, analysis, and communication. | G12: A | H12: DS §1.1 data science cycle (LO 1.1.2). | I12: In-scope | J12: 3 | K12: DS §1.1 LO 1.1.2: 'explain the data science cycle and goals of each step'. | M12: Agree with the resolution
A13: Q039 | B13: How do you read a Python error message and traceback to locate a bug? | C13: Tangential | D13: just mention in python book | E13: In-scope | F13: The Python text explains error messages and tracebacks for locating faults. | G13: A | H13: PY §1.6 Error messages (25 hits, traceback examples). | I13: In-scope | J13: 3 | K13: PY §1.6 Error messages: dedicated section, 25 mentions, worked traceback examples. | M13: Agree with the resolution
A14: Q041 | B14: Compare lists, tuples, and dictionaries in terms of mutability and typical use cases. | C14: Tangential | E14: In-scope | F14: Lists, tuples, and dictionaries are covered with mutability and use distinctions. | G14: A | H14: PY p.96–97 + dict ch.10 (multi-chunk). | I14: In-scope | J14: 1+3 | K14: PY p.96–97 mutability + ch.10 dictionaries; multi-chunk synthesis is by design. | M14: Agree with the resolution
A15: Q044 | B15: Compare searching an unsorted list, a sorted list with binary search, and a dictionary lookup. | C15: Out-of-scope | E15: In-scope | F15: The data-structures text covers linear search, binary search, and hash-table lookup. | G15: A | H15: PY §12.5 + ODS §6.2 + ODS ch.5. | I15: In-scope | J15: 1+3 | K15: PY §12.5 (linear vs binary search) + ODS §6.2 + ODS ch.5 (hash lookup). | M15: Agree with the resolution
A16: Q046 | B16: How would you find the maximum value in a list using loops and conditionals (no built-ins), and what is the complexity? | C16: Tangential | E16: In-scope | F16: Loops and conditionals are taught, and linear maximum-search complexity is supported. | G16: A | H16: PY loops/conditionals chs.4–5 + ODS complexity §1.3.3 (synthesis). | I16: In-scope | J16: 1 | K16: Loops+conditionals taught (PY chs.4–5); complexity of linear scan from ODS §1.3.3. | M16: Agree with the resolution
A17: Q048 | B17: What roles do training data and evaluation metrics each play in judging whether a model generalises? | C17: Out-of-scope | E17: In-scope | F17: Training data, evaluation metrics, validation, and generalisation are covered. | G17: A | H17: DS §6.1 (LO 6.1.2 training/testing, 6.1.3 accuracy measures). | I17: In-scope | J17: 3 | K17: DS §6.1 LOs 6.1.2–6.1.4: training/testing roles, accuracy measures, overfitting. | M17: Agree with the resolution
A18: Q049 | B18: How do encapsulation and abstraction work together in class design? | C18: Tangential | D18: Both are mentioned in SE book | E18: In-scope | F18: The Python OOP material explains abstraction and encapsulation in class design. | G18: A | H18: PY §11.1 both defined p.275,277. | I18: In-scope | J18: 3 | K18: PY §11.1 defines and relates both (p.275–277) — Python book, not SE book. | M18: Agree with the resolution
A19: Q050 | B19: Compare recursive and loop-based implementations of factorial: how does each work, and when is each preferable? | C19: Tangential | E19: In-scope | F19: The Python text demonstrates recursive and loop-based factorial approaches. | G19: A | H19: PY §12.2 factorial recursion + ch.5 loops. | I19: In-scope | J19: 3 | K19: PY §12.2 recursive factorial + ch.5 loop equivalents; §12.1 discusses when recursion helps. | M19: Agree with the resolution
A20: Q051 | B20: If two names point to the same container and I change it through one name, why does the other see the change? | C20: Tangential | E20: In-scope | F20: Python aliasing and mutation of shared mutable objects are covered. | G20: A | H20: PY §3.3 p.79–80: 'multiple variables may refer to the same object' + memory diagrams. | I20: In-scope | J20: 1+3 | K20: PY §3.3: 'multiple variables may refer to the same object' + memory diagrams — exactly this question. | M20: Agree with the resolution
A21: Q052 | B21: Why does my function give back nothing when I leave out a particular statement at the end? | C21: Out-of-scope | E21: In-scope | F21: Python function return behaviour when return is omitted is covered. | G21: A | H21: PY §6.5 p.173–174: missing return = returns None. | I21: In-scope | J21: 1+3 | K21: PY §6.5 p.173–174: omitting return = returns None. Paraphrase judged on concept. | M21: Agree with the resolution
A22: Q053 | B22: What mechanism lets me write a blueprint once and stamp out many working copies, each with its own data? | C22: Out-of-scope | E22: In-scope | F22: Python classes and instances support the blueprint-and-independent-object explanation. | G22: A | H22: PY p.277: 'a class is a blueprint for creating objects'. | I22: In-scope | J22: 1+3 | K22: PY p.277: 'a class is a blueprint for creating objects' — near-verbatim answer. | M22: Agree with the resolution
A23: Q054 | B23: Why is finding something by name in a phone-book-style structure faster than scanning a shopping list? | C23: Out-of-scope | E23: In-scope | F23: The data-structures text explains faster keyed lookup versus linear scanning. | G23: A | H23: DS p.86 (key-value efficient retrieval) + ODS ch.5. | I23: In-scope | J23: 1+3 | K23: DS p.86 (key-value = efficient retrieval) + ODS ch.5 hashing analysis. | M23: Agree with the resolution
A24: Q057 | B24: Why might a model ace the questions it studied but fail the real exam? | C24: Out-of-scope | E24: In-scope | F24: The data-science text explains overfitting and validation on new data. | G24: A | H24: DS p.267: fits known data, fails future data. | I24: In-scope | J24: 1+3 | K24: DS p.267: fits known data, fails future data = overfitting. Concept rule. | M24: Agree with the resolution
A25: Q058 | B25: What practice lets a team rewind their project to last week's working state? | C25: Out-of-scope | E25: In-scope | F25: Version control is explained as tracking project history and recovering prior states. | G25: A | H25: DS p.480. | I25: In-scope | J25: 1+3 | K25: DS p.480: version control defined incl. recovering prior states. Concept rule. | M25: Agree with the resolution
A26: Q059 | B26: Why do some approaches slow down disproportionately as the input grows, while others stay manageable? | C26: Out-of-scope | E26: In-scope | F26: Explained by Open Data Structures coverage of running-time growth and asymptotic analysis. | G26: A | H26: ODS §1.3.3 + p.14 growth-rate reasoning. | I26: In-scope | J26: 1+3 | K26: ODS §1.3.3 asymptotics + p.14 growth-rate worked example. Concept rule. | M26: Agree with the resolution
A27: Q064 | B27: How does CPython's garbage collector handle reference cycles? | C27: Tangential | D27: just one mention in DS book | E27: Out-of-scope | F27: CPython garbage collection and reference-cycle handling are not covered. | G27: B | H27: 'Garbage collection' = literal trash bins in a smart-city example. No CPython GC. | I27: Tangential | J27: 2 | K27: Python objects/references taught (PY §3.3); CPython GC internals absent. Adjacent topic covered → Tangential. | L27: Out of scope, the objects/references are taught but not garbage collection, and CPython especially does garbage collection too differently for it to be considered tangential here. | M27: Agree that this should be out of scope
A28: Q065 | B28: What are Python descriptors and how do properties use them? | C28: Out-of-scope | E28: Tangential | F28: Object-oriented features are covered, but Python descriptors and their relationship to properties are not. | G28: B | H28: Machine-verified absent (lexical, normalized, 4 books) | I28: Tangential | J28: 2 | K28: Python OOP/properties-adjacent material covered; descriptors absent → Tangential. | M28: Agree with the resolution
A29: Q068 | B29: How does a B+ tree differ from a B tree for database indexing? | C29: Out-of-scope | E29: In-scope | F29: Open Data Structures describes B+ trees in relation to B-trees and external-memory indexing. | G29: B | H29: M's basis is factually wrong: 'B+ tree' has ZERO hits in all four books (B-trees yes, ODS ch.14). Under the boundary rule below → Tangential. | I29: Tangential | J29: 2+3 | K29: B-trees taught in depth (ODS ch.14); 'B+ tree' has ZERO hits in all books (M's basis factually wrong) → Tangential. | L29: Incorrent. It is taught properly in the book, there were zero hits because it is written as B then superscript + trees. There is also an illustration of the same present as well. Check §14.3 of the ODS book, present on page 311 of the pdf. | M29: Agree with the resolution of in-scope
A30: Q070 | B30: How does Timsort exploit pre-existing runs in real-world data? | C30: Out-of-scope | E30: Tangential | F30: Sorting is covered, but Timsort’s exploitation of natural runs is not explained. | G30: B | H30: Machine-verified absent (lexical, normalized, 4 books) | I30: Tangential | J30: 2 | K30: Sorting covered extensively (ODS ch.11); Timsort absent → Tangential. | M30: Agree with the resolution
A31: Q071 | B31: How do residual connections (as in ResNets) mitigate the vanishing-gradient problem in very deep networks? | C31: Tangential | E31: Out-of-scope | F31: Residual connections and ResNets are not covered. | G31: B | H31: Vanishing gradients ARE covered (DS, 4 pages); ResNets absent. Under the boundary rule → Tangential (V's label). | I31: Tangential | J31: 2+3 | K31: Vanishing gradients covered (DS, 4 pages); ResNets absent → Tangential. | L31: Agreed
A32: Q076 | B32: How do you configure a CI/CD pipeline for releasing a Python package? | C32: Out-of-scope | E32: Tangential | F32: The texts discuss Python and version control, but not configuring a release CI/CD pipeline. | G32: B | H32: Machine-verified absent (lexical, normalized, 4 books) | I32: Tangential | J32: 2 | K32: SE process/release practices covered; CI/CD absent → Tangential. | M32: Agree with the resolution
A33: Q080 | B33: How does NumPy's stride-based memory layout enable broadcasting? | C33: Out-of-scope | E33: Tangential | F33: NumPy is covered, but stride-based memory layout and its role in broadcasting are not explained. | G33: B | H33: Machine-verified absent (lexical, normalized, 4 books) | I33: Tangential | J33: 2 | K33: NumPy taught (PY §15.2); strides/broadcasting internals absent → Tangential. | M33: Agree with the resolution
A34: Q097 | B34: Based on the object-oriented programming chapter, what design patterns does the Unreal Engine source code use? | C34: Out-of-scope | E34: Tangential | F34: The OOP material supports design-pattern concepts, but not an analysis of Unreal Engine source code. | G34: B | H34: Re-adjudicated: 'unreal' hit in SE is the word 'unrealistic'. Still absent. | I34: Out-of-scope | J34: 2 | K34: Premise targets external artifact (Unreal Engine source) → OOS despite OOP vocabulary. | L34: the question technically falls in both categories, better to reframe the question as per the label since Unreal Engine is not covered anywhere however the design patterns of OOP is covered. Hence this can be considered both tangential as well as out of scope based on user interpretation.
A35: Q098 | B35: Given the corpus's coverage of binary search, what is the exact implementation of Java's Arrays.binarySearch? | C35: Out-of-scope | E35: Tangential | F35: Binary search is covered, but Java Arrays.binarySearch implementation details are not. | G35: B | H35: Java appears only in hello-world comparison; Arrays.binarySearch absent. | I35: Out-of-scope | J35: 2 | K35: Premise targets external artifact (Java stdlib implementation) → OOS. | L35: Again, on a technicality it is out of scope, however the core concept of how binary search works is covered, just the exact implementation to the T for java's binary search is not covered. I suggest tangential. | M35: Agree with marking this as Tangential
A36: Q099 | B36: Applying the data-cleaning workflow from the textbook, how should MRI scans be preprocessed for a radiology pipeline? | C36: Out-of-scope | E36: Tangential | F36: Data cleaning is covered, but MRI-specific radiology preprocessing is not. | G36: B | H36: Machine-verified absent (lexical, normalized, 4 books) | I36: Out-of-scope | J36: 2 | K36: Premise targets external domain (MRI/radiology) → OOS despite workflow vocabulary. | L36: Again, the core concept is covered. however this particular question i feel falls more on the out of scope end.
A37: Q100 | B37: Using the machine learning basics chapter, explain GPT-4's mixture-of-experts architecture. | C37: Out-of-scope | E37: Tangential | F37: Machine-learning basics are covered, but GPT-4 mixture-of-experts architecture is not. | G37: B | H37: GPT-4 name-dropped in NLP history (Table 7.3); mixture-of-experts absent. | I37: Out-of-scope | J37: 2 | K37: Premise targets external artifact (GPT-4 architecture) → OOS. | L37: Yet again, because of how the question is framed it is ambiguous, ML is covered but the exact GPT arch is not covered. Could be considered both, I suggest tangential.
A38: Q119 | B38: What is technical debt and how does it accumulate? | C38: Tangential | D38: just mentions in SE book | E38: In-scope | F38: Covered directly: the handbook explains technical debt, how poor decisions accumulate it, and refactoring as repayment. | G38: A | H38: SE p.74 (case study) + p.94. | I38: In-scope | J38: 3 | K38: SE glossary defines technical debt; p.94 explains accumulation via sloppy code; p.74 case study. | M38: Agree with the resolution
A39: Q123 | B39: Compare arrays and linked lists for insertion, deletion, and random access complexity. | C39: Tangential | E39: In-scope | F39: Array and linked-list insertion, deletion, access, and running times are covered. | G39: A | H39: ODS chs.2–3 with per-structure complexity summaries. | I39: In-scope | J39: 3 | K39: ODS chs.2–3 give per-operation running times for array-based and linked lists. | M39: Agree with the resolution
A40: Q124 | B40: Why does a hash table offer O(1) expected lookup while a binary search tree offers O(log n), and when would you still prefer the tree? | C40: Tangential | E40: In-scope | F40: Hash tables and binary search trees are covered with their expected lookup trade-offs. | G40: A | H40: ODS ch.5 + §6.2 + p.21 (USet vs SSet guidance). | I40: In-scope | J40: 3 | K40: ODS ch.5 (expected O(1)) + §6.2/ch.9 (O(log n)) + p.21 USet-vs-SSet guidance (when to prefer tree). | M40: Agree with the resolution
A41: Q125 | B41: Compare merge sort and quicksort in worst-case behaviour and memory use. | C41: Tangential | D41: few mentions in ODS book | E41: In-scope | F41: Merge sort and quicksort are covered with time and space behaviour. | G41: A | H41: ODS §11.1 explicit comparisons incl. lower bound. | I41: In-scope | J41: 3 | K41: ODS §11.1 treats merge/quick incl. worst cases, in-place vs auxiliary array, lower bound. | M41: Agree with the resolution
...

Sheet Adjudication rules & log
A1: ADJUDICATION RULES (applied to all 46 disagreements on 21-Jul-2026)
A2: Rule 1 — Concept rule: a question is judged on whether the corpus answers its underlying concept, not whether the
A3: question's wording appears in the text. Paraphrase disguise tests the retrieval system, not the annotator.
A4: Rule 2 — Boundary rule: TANGENTIAL if the corpus covers the adjacent topic but not the asked specifics;
A5: OUT-OF-SCOPE if the premise targets content wholly outside the corpus (unrelated domain, external artifact,
A6: or false premise about the corpus), regardless of vocabulary overlap.
A7: Rule 3 — Evidence rule: factual disputes ('does the book teach X?') are settled by verified page evidence.
A9: PROVENANCE & RATIFICATION STATUS
A10: Rules written and applied by Claude (Anthropic) at the corresponding author's request; per-row reasoning is appended
A11: to each row's Notes on the Questions sheet and shown on the Adjudication guide sheet.
A12: PENDING: both annotators (V. Ramachandran, M. Vedanta) must review the 46 resolutions and confirm by email
A13: ('ratified' or row-specific vetoes) BEFORE the benchmark is frozen. Do not freeze without both confirmations.
... A19: Q068 In-scope CONFIRMED by V (03-Aug-2026). RATIFICATION COMPLETE FOR ALL 150 ROWS — BENCHMARK IS FREEZE-READY.

Sheet Instructions & stats
A1: 150-Question Benchmark v3 — Four-Book Corpus
A2: Corpus: Intro to Python Programming + Principles of Data Science (OpenStax), Open Data Structures (Morin, CC BY),
A3: Handbook of Software Engineering Methods (Letaw, CC BY-NC). Q101–Q150 added and Q067/Q069 rewritten 21-Jul-2026.
A5: Composition
A6: In-scope direct | B6: =COUNTIF(Questions!$B$2:$B$151,"In-scope direct")
A7: In-scope hard | B7: =COUNTIF(Questions!$B$2:$B$151,"In-scope hard")
A8: Tangential | B8: =COUNTIF(Questions!$B$2:$B$151,"Tangential")
A9: Out-of-scope | B9: =COUNTIF(Questions!$B$2:$B$151,"Out-of-scope")
A10: Total | B10: =COUNTA(Questions!$A$2:$A$151)
A12: Verification status
A13: Verified absent (machine + adjudicated) | B13: =COUNTIF(Questions!$G$2:$G$151,"Verified absent")
A14: Needs human check (in-scope) | B14: =COUNTIF(Questions!$G$2:$G$151,"Needs human check")
A15: Verified in corpus | B15: =COUNTIF(Questions!$G$2:$G$151,"Verified in corpus")
A16: Rejected - rewrite | B16: =COUNTIF(Questions!$G$2:$G$151,"Rejected - rewrite")
A18: Human progress
A19: Dual-labelled | B19: =COUNTIF(Questions!$K$2:$K$151,"Agree")+COUNTIF(Questions!$K$2:$K$151,"DISAGREE")
A20: Inter-annotator agreement | B20: =IF(B19=0,"",COUNTIF(Questions!$K$2:$K$151,"Agree")/B19)
A23: Notes
A24: IMPORTANT: this benchmark targets the FOUR-book corpus. Results are not comparable with anything run on the old two-book index.
A25: Rebuild the FAISS index from the expanded Dataset folder before any evaluation run (same config: bge-base-en-v1.5, 1000/200).
A27: DONE (machine + Claude adjudication): all 60 tangential/OOS rows are 'Verified absent' — reasoning in Notes; spot-check advised.
A28: TODO (human): 90 'Needs human check' in-scope rows — open cited pages, confirm the text answers the question, set status.
A29: TODO (two humans): independent Annotator 1/2 labels; adjudicate DISAGREE rows; record Final label. Then FREEZE (git tag/hash).
A31: Corpus-change history: Q067 (red-black trees) and Q069 (Fibonacci-heap decrease-key) were REJECTED because Open Data Structures
A32: teaches both (ODS Ch.9; ODS §10.3 states the decrease-key answer verbatim) — rewritten to consistent hashing and splay trees.
A33: Q068/Q095/Q097 were re-adjudicated for the new corpus (see their Notes).
A35: Paper note: with the two added books, Section IV-A's claimed coverage ('data structures and algorithms', 'software engineering
A36: concepts') is now genuinely supported — but cite all four books and their licenses (CC BY / CC BY-NC) in the Dataset section.
A38: Disclosure sentence: 'Benchmark questions were drafted with LLM assistance (Claude, Anthropic — a model family distinct from the
... A44: each rewrite verified against an explicit section. Remaining human work: spot-check sample + independent dual labelling.
